{
 "cells": [
  {
   "cell_type": "code",
   "execution_count": 1,
   "id": "a9b5233a-471f-4451-8986-ea73e504c0db",
   "metadata": {},
   "outputs": [],
   "source": [
    "#created at 20250201"
   ]
  },
  {
   "cell_type": "code",
   "execution_count": null,
   "id": "694d3625-7586-4b5c-81ac-3a0a4d242722",
   "metadata": {},
   "outputs": [],
   "source": [
    "https://stevejoe1412.gitbook.io/ssn/python-subtopics/asynchronous-programming"
   ]
  },
  {
   "cell_type": "code",
   "execution_count": null,
   "id": "0feb0bfe-ef07-437f-842f-dc2c42f9e881",
   "metadata": {},
   "outputs": [],
   "source": [
    "#Running multiple tasks concurrently"
   ]
  },
  {
   "cell_type": "code",
   "execution_count": 2,
   "id": "081aeb52-b1e3-47cc-ac6a-8b4453de93c9",
   "metadata": {},
   "outputs": [],
   "source": [
    "import asyncio"
   ]
  },
  {
   "cell_type": "code",
   "execution_count": 4,
   "id": "31a81c74-caac-4f1f-8fb3-3e3e01a27e4b",
   "metadata": {},
   "outputs": [],
   "source": [
    "async def task1():\n",
    "    print(\"task1 is started\")\n",
    "    await asyncio.sleep(2)\n",
    "    print(\"task1 is completed\")"
   ]
  },
  {
   "cell_type": "code",
   "execution_count": 5,
   "id": "e45d141b-5539-460f-8ea2-ff7e6b358704",
   "metadata": {},
   "outputs": [],
   "source": [
    "async def task2():\n",
    "    print(\"task2 is started\")\n",
    "    await asyncio.sleep(1)\n",
    "    print(\"task2 is completed\")"
   ]
  },
  {
   "cell_type": "code",
   "execution_count": 6,
   "id": "77c21f78-0152-4195-99ec-bff131509ceb",
   "metadata": {},
   "outputs": [
    {
     "ename": "RuntimeError",
     "evalue": "asyncio.run() cannot be called from a running event loop",
     "output_type": "error",
     "traceback": [
      "\u001b[0;31m---------------------------------------------------------------------------\u001b[0m",
      "\u001b[0;31mRuntimeError\u001b[0m                              Traceback (most recent call last)",
      "Cell \u001b[0;32mIn[6], line 4\u001b[0m\n\u001b[1;32m      1\u001b[0m \u001b[38;5;28;01masync\u001b[39;00m \u001b[38;5;28;01mdef\u001b[39;00m\u001b[38;5;250m \u001b[39m\u001b[38;5;21mmain\u001b[39m():\n\u001b[1;32m      2\u001b[0m     \u001b[38;5;28;01mawait\u001b[39;00m asyncio\u001b[38;5;241m.\u001b[39mgather(task1, task2())\n\u001b[0;32m----> 4\u001b[0m \u001b[43masyncio\u001b[49m\u001b[38;5;241;43m.\u001b[39;49m\u001b[43mrun\u001b[49m\u001b[43m(\u001b[49m\u001b[43mmain\u001b[49m\u001b[43m(\u001b[49m\u001b[43m)\u001b[49m\u001b[43m)\u001b[49m\n",
      "File \u001b[0;32m~/miniconda3/envs/py312/lib/python3.12/asyncio/runners.py:190\u001b[0m, in \u001b[0;36mrun\u001b[0;34m(main, debug, loop_factory)\u001b[0m\n\u001b[1;32m    161\u001b[0m \u001b[38;5;250m\u001b[39m\u001b[38;5;124;03m\"\"\"Execute the coroutine and return the result.\u001b[39;00m\n\u001b[1;32m    162\u001b[0m \n\u001b[1;32m    163\u001b[0m \u001b[38;5;124;03mThis function runs the passed coroutine, taking care of\u001b[39;00m\n\u001b[0;32m   (...)\u001b[0m\n\u001b[1;32m    186\u001b[0m \u001b[38;5;124;03m    asyncio.run(main())\u001b[39;00m\n\u001b[1;32m    187\u001b[0m \u001b[38;5;124;03m\"\"\"\u001b[39;00m\n\u001b[1;32m    188\u001b[0m \u001b[38;5;28;01mif\u001b[39;00m events\u001b[38;5;241m.\u001b[39m_get_running_loop() \u001b[38;5;129;01mis\u001b[39;00m \u001b[38;5;129;01mnot\u001b[39;00m \u001b[38;5;28;01mNone\u001b[39;00m:\n\u001b[1;32m    189\u001b[0m     \u001b[38;5;66;03m# fail fast with short traceback\u001b[39;00m\n\u001b[0;32m--> 190\u001b[0m     \u001b[38;5;28;01mraise\u001b[39;00m \u001b[38;5;167;01mRuntimeError\u001b[39;00m(\n\u001b[1;32m    191\u001b[0m         \u001b[38;5;124m\"\u001b[39m\u001b[38;5;124masyncio.run() cannot be called from a running event loop\u001b[39m\u001b[38;5;124m\"\u001b[39m)\n\u001b[1;32m    193\u001b[0m \u001b[38;5;28;01mwith\u001b[39;00m Runner(debug\u001b[38;5;241m=\u001b[39mdebug, loop_factory\u001b[38;5;241m=\u001b[39mloop_factory) \u001b[38;5;28;01mas\u001b[39;00m runner:\n\u001b[1;32m    194\u001b[0m     \u001b[38;5;28;01mreturn\u001b[39;00m runner\u001b[38;5;241m.\u001b[39mrun(main)\n",
      "\u001b[0;31mRuntimeError\u001b[0m: asyncio.run() cannot be called from a running event loop"
     ]
    }
   ],
   "source": [
    "async def main():\n",
    "    await asyncio.gather(task1, task2())\n",
    "\n",
    "asyncio.run(main())"
   ]
  },
  {
   "cell_type": "code",
   "execution_count": null,
   "id": "cbb63147-9590-444a-82bd-f9c99b2b2c00",
   "metadata": {},
   "outputs": [],
   "source": []
  }
 ],
 "metadata": {
  "kernelspec": {
   "display_name": "Python 3 (ipykernel)",
   "language": "python",
   "name": "python3"
  },
  "language_info": {
   "codemirror_mode": {
    "name": "ipython",
    "version": 3
   },
   "file_extension": ".py",
   "mimetype": "text/x-python",
   "name": "python",
   "nbconvert_exporter": "python",
   "pygments_lexer": "ipython3",
   "version": "3.12.8"
  }
 },
 "nbformat": 4,
 "nbformat_minor": 5
}
