---
title: Ex-10
date: 2025-04-21
author: Your Name
cell_count: 8
score: 5
---

```python
#created at 20250415
```


```python
#Multiple Exception Handling 
```


```python
print("\n === Multiple Exception Handling ===")
```

    
     === Multiple Exception Handling ===



```python
def process_data(data):
    try:
        value = int(data)
        result = 100/value
        print(f"result:{result}")
    except (valueError, ZeroDivisionError) as e:
        print(f"Error occured:{type(e).__name__}")
```


```python
process_data('abc')
```


    ---------------------------------------------------------------------------

    ValueError                                Traceback (most recent call last)

    Cell In[2], line 3, in process_data(data)
          2 try:
    ----> 3     value = int(data)
          4     result = 100/value


    ValueError: invalid literal for int() with base 10: 'abc'

    
    During handling of the above exception, another exception occurred:


    NameError                                 Traceback (most recent call last)

    Cell In[3], line 1
    ----> 1 process_data('abc')


    Cell In[2], line 6, in process_data(data)
          4     result = 100/value
          5     print(f"result:{result}")
    ----> 6 except (valueError, ZeroDivisionError) as e:
          7     print(f"Error occured:{type(e).__name__}")


    NameError: name 'valueError' is not defined



```python

```


```python


```


```python

```


---
**Score: 5**