---
title: Ex-9-9958
date: 2025-04-29
author: Your Name
cell_count: 7
score: 5
---

```python
#created at 20250308
```


```python
#https://stevejoe1412.gitbook.io/ssn/python-subtopics/2.-asynchronous-programming
```


```python
#event loop with asyncio.create_task
```


```python
import asyncio
```


```python
async def print_numbers():
    for i in range(5):
        print(f"Number:{i}")
        await asyncio.sleep(1)
```


```python
async def main():
    task = asyncio.create_task(print_numbers())
    print("Task created")
    await asyncio.sleep(3)
    print("Main task comppleted")
    await task

asyncio.run(main())
```


    ---------------------------------------------------------------------------

    RuntimeError                              Traceback (most recent call last)

    Cell In[4], line 8
          5     print("Main task comppleted")
          6     await task
    ----> 8 asyncio.run(main())


    File ~/miniconda3/envs/py312/lib/python3.12/asyncio/runners.py:190, in run(main, debug, loop_factory)
        161 """Execute the coroutine and return the result.
        162 
        163 This function runs the passed coroutine, taking care of
       (...)
        186     asyncio.run(main())
        187 """
        188 if events._get_running_loop() is not None:
        189     # fail fast with short traceback
    --> 190     raise RuntimeError(
        191         "asyncio.run() cannot be called from a running event loop")
        193 with Runner(debug=debug, loop_factory=loop_factory) as runner:
        194     return runner.run(main)


    RuntimeError: asyncio.run() cannot be called from a running event loop



```python

```


---
**Score: 5**