---
title: Ex-5-9579
date: 2025-04-21
author: Your Name
cell_count: 7
score: 5
---

```python
#created at 20250314
```


```python
#https://stevejoe1412.gitbook.io/ssn/python-subtopics/10.-mocking-in-unit-tests
```


```python
#Mocking an object Attribute
```


```python
from unittest.mock import patch
```


```python
class MyClass:
    attribute = "original value"
```


```python
with patch.object(MyClass,"Attribute","Mocked value"):
    print(MyClass.attribute)
```


    ---------------------------------------------------------------------------

    AttributeError                            Traceback (most recent call last)

    Cell In[7], line 1
    ----> 1 with patch.object(MyClass,"Attribute","Mocked value"):
          2     print(MyClass.attribute)


    File ~/miniconda3/envs/py312/lib/python3.12/unittest/mock.py:1467, in _patch.__enter__(self)
       1463 if ((spec is not None or autospec is not None) and
       1464     spec_set not in (True, None)):
       1465     raise TypeError("Can't provide explicit spec_set *and* spec or autospec")
    -> 1467 original, local = self.get_original()
       1469 if new is DEFAULT and autospec is None:
       1470     inherit = False


    File ~/miniconda3/envs/py312/lib/python3.12/unittest/mock.py:1437, in _patch.get_original(self)
       1434     self.create = True
       1436 if not self.create and original is DEFAULT:
    -> 1437     raise AttributeError(
       1438         "%s does not have the attribute %r" % (target, name)
       1439     )
       1440 return original, local


    AttributeError: <class '__main__.MyClass'> does not have the attribute 'Attribute'



```python

```


---
**Score: 5**