---
title: Ex-10-3496
date: 2025-03-26
author: Your Name
cell_count: 7
score: 5
---

```python
#creatd at 20250314
```


```python
#https://stevejoe1412.gitbook.io/ssn/python-subtopics/8.-coroutines
```


```python
#Coroutine with Asynchronous Behavior Using asyncio
```


```python
import asyncio
```


```python
async def async_coroutine():
    print("coroutine started")
    await asyncio.sleep(1)
    print("coroutine resumed")
```


```python
asyncio.run(async_coroutine())
```

    /home/arnald/miniconda3/envs/py312/lib/python3.12/site-packages/pygments/regexopt.py:77: RuntimeWarning: coroutine 'async_coroutine' was never awaited
      '|'.join(regex_opt_inner(list(group[1]), '')
    RuntimeWarning: Enable tracemalloc to get the object allocation traceback



    ---------------------------------------------------------------------------

    RuntimeError                              Traceback (most recent call last)

    Cell In[8], line 1
    ----> 1 asyncio.run(async_coroutine())


    File ~/miniconda3/envs/py312/lib/python3.12/asyncio/runners.py:190, in run(main, debug, loop_factory)
        161 """Execute the coroutine and return the result.
        162 
        163 This function runs the passed coroutine, taking care of
       (...)
        186     asyncio.run(main())
        187 """
        188 if events._get_running_loop() is not None:
        189     # fail fast with short traceback
    --> 190     raise RuntimeError(
        191         "asyncio.run() cannot be called from a running event loop")
        193 with Runner(debug=debug, loop_factory=loop_factory) as runner:
        194     return runner.run(main)


    RuntimeError: asyncio.run() cannot be called from a running event loop



```python

```


---
**Score: 5**