---
title: Ex-9-7699
date: 2025-04-26
author: Your Name
cell_count: 7
score: 5
---

```python
#created at 20250315
```


```python
#https://stevejoe1412.gitbook.io/ssn/python-subtopics/14.-custom-exceptions
```


```python
#custom Exception for Invalid Input
```


```python
class InvaidInputError(Exception):
    def __init__(self, input_value, message = "Invalid input"):
        self.input_value = input_value
        self.message = message
        super().__init__(self.message)
```


```python
def process_input(value):
    if not isinstance(value, int):
        raise InvalidInputError(value)
    return value * 2
```


```python
try:
    process_input("string")
except InvalidInputError as e:
    print(f"Error:{e}")
```


    ---------------------------------------------------------------------------

    NameError                                 Traceback (most recent call last)

    Cell In[3], line 2
          1 try:
    ----> 2     process_input("string")
          3 except InvalidInputError as e:


    Cell In[2], line 3, in process_input(value)
          2 if not isinstance(value, int):
    ----> 3     raise InvalidInputError(value)
          4 return value * 2


    NameError: name 'InvalidInputError' is not defined

    
    During handling of the above exception, another exception occurred:


    NameError                                 Traceback (most recent call last)

    Cell In[3], line 3
          1 try:
          2     process_input("string")
    ----> 3 except InvalidInputError as e:
          4     print(f"Error:{e}")


    NameError: name 'InvalidInputError' is not defined



```python

```


---
**Score: 5**